Workbook
Name w: #REF!

Sheet Master
A1: Database
A2: Harga Bahan, Alat & Perlengkapan
A3: The Soko Coffee Tea Chocolate
B5: 1 | C5: 2 | D5: 3 | E5: 4 | F5: 5 | G5: 6 | H5: 7 | I5: 8 | J5: 9 | K5: 10 | L5: 11 | M5: 12 | N5: 13
A6: No | B6: Remark | C6: Kode | D6: Divisi | E6: Sub Divisi | F6: Jenis | G6: Price (Rp) | H6: Unit Pack | I6: Qty | J6: Unit | K6: Price/Unit | L6: Toko Belanja | M6: Jenis Belanja | N6: Keterangan | P6: Divisi | R6: Kategori | T6: Kategori Menu | V6: Menu | W6: SKU | Y6: Jenis Bahan | AA6: Unit Pack | AC6: Toko Belanja | AD6: Sales PIC | AE6: Alamat | AF6: No Hp / WA | AG6: Jenis Belanja | AH6: Ket. Barang Masuk
A7: 1 | B7: Ktc Pro Acar | C7: P01 | D7: Kitchen | E7: KTC Kitchen | G7: =VLOOKUP(B7,'Production Kitchen'!$B$5:$L$1029,10,FALSE) -> 321.82692 | I7: 1 | J7: ml | K7: =G7/I7 -> 321.82692 | P7: Office | R7: Bahan Kopi | T7: Coffee | V7: Cappucino Hot | W7: M0001 | Y7: Bar Coffee | AA7: Kilogram | AC7: PT Sukanda Djaya | AD7: Kang Ahmat | AF7: 085157020709 | AG7: Supplier | AH7: H+1
A8: =A7+1 -> 2 | B8: Ktc Pro Bawang Goreng | C8: P02 | D8: Kitchen | E8: KTC Kitchen | G8: =VLOOKUP(B8,'Production Kitchen'!$B$5:$L$1029,10,FALSE) -> 450.70667 | I8: 1 | J8: gr/por | K8: =G8/I8 -> 450.70667 | P8: Marketing | R8: Bahan Non-Kopi | T8: Manual Brewing | V8: Cappucino Ice | W8: M0002 | Y8: Bar Powder | AA8: Can | AC8: Danone | AG8: Supplier | AH8: Setiap Jumat, Tagihan Akhir Bulan
A9: =A8+1 -> 3 | B9: Ktc Pro Cream Soup | C9: P03 | D9: Kitchen | E9: KTC Kitchen | G9: =VLOOKUP(B9,'Production Kitchen'!$B$5:$L$1029,10,FALSE) -> 5583.677 | I9: 1 | J9: gr/ml | K9: =G9/I9 -> 5583.677 | P9: Floor | R9: Bahan Kitchen | T9: Chocolate & Tea | V9: Iced Cafe Latte | W9: M0003 | Y9: Bar Syrup Puree Concentrate | AA9: Pack | AC9: PT Fatarindo Cemerlang | AD9: Dedi | AF9: 081222294407 | AG9: Supplier | AH9: Setiap Rabu, Langsung Bayar
A10: =A9+1 -> 4 | B10: Ktc Pro Sauce Blackpepper | C10: P04 | D10: Kitchen | E10: KTC Kitchen | G10: =VLOOKUP(B10,'Production Kitchen'!$B$5:$L$1029,10,FALSE) -> 1363.1871 | I10: 1 | J10: gr/por | K10: =G10/I10 -> 1363.1871 | P10: Gudang Pusat | R10: Bahan Dessert & Bakery | T10: Milk Base | V10: Hot Cafe Latte | W10: M0004 | Y10: Bar Milk | AA10: Bag | AC10: LMK | AF10: 081322588522 | AG10: Supplier
A11: =A10+1 -> 5 | B11: Ktc Pro Pancake | C11: P05 | D11: Kitchen | E11: KTC Kitchen | G11: =VLOOKUP(B11,'Production Kitchen'!$B$5:$L$1029,10,FALSE) -> 5764.8067 | I11: 1 | J11: gr/slice | K11: =G11/I11 -> 5764.8067 | P11: Bar | R11: Bahan Bar | T11: Mocktail & Squash | V11: Hot Americano | W11: M0005 | Y11: Bar Tea | AA11: Pail | AC11: Toffico | AG11: Supplier
A12: =A11+1 -> 6 | B12: Ktc Pro Choco Lava | C12: P06 | D12: Kitchen | E12: KTC Kitchen | G12: =VLOOKUP(B12,'Production Kitchen'!$B$5:$L$1029,10,FALSE) -> 4952.75 | I12: 1 | J12: gr/por | K12: =G12/I12 -> 4952.75 | P12: Dessert & Bakery | R12: KTC Bar | T12: Signature | V12: Iced Americano | W12: M0006 | Y12: Bar Water | AA12: Bottle | AC12: PD Sentosa | AD12: Sendi | AF12: 085799626000 | AG12: Supplier
A13: =A12+1 -> 7 | B13: Ktc Pro Sauce Barbeque | C13: P07 | D13: Kitchen | E13: KTC Kitchen | G13: =VLOOKUP(B13,'Production Kitchen'!$B$5:$L$1029,10,FALSE) -> 537.32381 | I13: 1 | J13: Porsi | K13: =G13/I13 -> 537.32381 | P13: Kitchen | R13: KTC Kitchen | T13: Main Course & Bowl | V13: Hot Moccacino | W13: M0007 | Y13: Bar Fruit | AA13: Galon | AC13: Dillco Group | AD13: Iqbal | AF13: 089663452433 | AG13: Supplier
A14: =A13+1 -> 8 | B14: Ktc Pro Sauce Bolognaise | C14: P08 | D14: Kitchen | E14: KTC Kitchen | G14: =VLOOKUP(B14,'Production Kitchen'!$B$5:$L$1029,10,FALSE) -> 2300.1407 | I14: 1 | J14: gr/pcs | K14: =G14/I14 -> 2300.1407 | P14: Bar & Kitchen | R14: KTC Dessert & Bakery | T14: Light Meals | V14: Iced Moccacino | W14: M0008 | Y14: Bar Groceries | AA14: Crat | AC14: Woodlane | AD14: Vikar | AF14: 081324510971 | AG14: Supplier
A15: =A14+1 -> 9 | B15: Ktc Pro White Sauce | C15: P09 | D15: Kitchen | E15: KTC Kitchen | G15: =VLOOKUP(B15,'Production Kitchen'!$B$5:$L$1029,10,FALSE) -> 1883.9883 | I15: 1 | J15: gr/por | K15: =G15/I15 -> 1883.9883 | P15: - | R15: Packing Bar | T15: Pizza & Pasta | V15: Hazelnut Latte Hot | W15: M0009 | Y15: Bar Packing | AA15: Tabung | AC15: Havilla Tea | AF15: 081221689133 | AG15: Supplier | AH15: Operasional Di Atas jam5 Sore
A16: =A15+1 -> 10 | B16: Ktc Pro RU Sauce | C16: P10 | D16: Kitchen | E16: KTC Kitchen | G16: =VLOOKUP(B16,'Production Kitchen'!$B$5:$L$1029,10,FALSE) -> 320.99737 | I16: 1 | J16: gr | K16: =G16/I16 -> 320.99737 | R16: Packing Kitchen | T16: Desserts | V16: Hazelnut Latte Ice | W16: M0010 | Y16: Ktc Meat | AA16: Dus | AC16: Geraldi Risol | AG16: Supplier
A17: =A16+1 -> 11 | B17: Ktc Pro Dough Pizza | C17: P11 | D17: Kitchen | E17: KTC Kitchen | G17: =VLOOKUP(B17,'Production Kitchen'!$B$5:$L$1029,10,FALSE) -> 2108.7129 | I17: 1 | J17: gr | K17: =G17/I17 -> 2108.7129 | R17: Packing Dessert & Bakery | T17: Menu Nusantara | V17: Hot Vanilla Latte | W17: M0011 | Y17: Ktc Vegetables | AC17: HOC | AG17: Supplier
A18: =A17+1 -> 12 | B18: Ktc Pro Sauce Moza | C18: P12 | D18: Kitchen | E18: KTC Kitchen | G18: =VLOOKUP(B18,'Production Kitchen'!$B$5:$L$1029,10,FALSE) -> 4554 | I18: 1 | J18: gr | K18: =G18/I18 -> 4554 | R18: Bahan Bar & Kitchen | T18: Menu Catering | V18: Iced Vanilla Latte | W18: M0012 | Y18: Ktc Bread Biscuit | AC18: Arghani | AF18: 087777112108 | AG18: Supplier
A19: =A18+1 -> 13 | B19: Tahu sambal kecap | C19: P13 | D19: Kitchen | E19: KTC Kitchen | G19: =VLOOKUP(B19,'Menu Kitchen'!$B$5:$K$2098,8,FALSE) -> 3809.2312 | I19: 1 | J19: gr | K19: =G19/I19 -> 3809.2312 | R19: BB Lain-lain | T19: Extra Kitchen | V19: Affogato | W19: M0013 | Y19: Ktc Groceries | AC19: Eden Farm | AD19: Lilis | AF19: 081383888715 | AG19: Distributor
A20: =A19+1 -> 14 | B20: Ktc Pro Sauce Bumbu Rujak | C20: P14 | D20: Kitchen | E20: KTC Kitchen | G20: =VLOOKUP(B20,'Production Kitchen'!$B$5:$L$1029,10,FALSE) -> 814.81481 | I20: 1 | J20: gr/slice | K20: =G20/I20 -> 814.81481 | R20: ATK | T20: KTC Bar | V20: Coconut Cream | W20: M0014 | Y20: Ktc Packing | AC20: Feri Supriadi (Telur , Beras , Minyak ) | AD20: Feri | AF20: 081312570820 | AG20: Distributor
A21: =A20+1 -> 15 | B21: Bakwan jagung sambal kecap | C21: P15 | D21: Kitchen | E21: KTC Kitchen | G21: =VLOOKUP(B21,'Menu Kitchen'!$B$5:$K$2098,8,FALSE) -> 5258.4812 | I21: 1 | J21: gr | K21: =G21/I21 -> 5258.4812 | R21: Service Mesin | T21: KTC Dessert & Bakery | V21: Es Kopi Soko | W21: M0015 | Y21: OP Groceries | AC21: BISS (Topside) | AD21: Ayu | AF21: 087736858365 | AG21: Supplier
A22: =A21+1 -> 16 | B22: Ktc Pro Cheese Sauce | C22: P16 | D22: Kitchen | E22: KTC Kitchen | G22: =VLOOKUP(B22,'Production Kitchen'!$B$5:$L$1029,10,FALSE) -> 1773.7816 | I22: 1 | J22: gr | K22: =G22/I22 -> 1773.7816 | R22: Bensin, Parkir, Transport | T22: KTC Kitchen | V22: Spring Berry Ice | W22: M0016 | AC22: Prima (Topside) | AD22: Maudi | AF22: 082116418738 | AG22: Supplier
A23: =A22+1 -> 17 | B23: Ktc Pro Onion Rings | C23: P17 | D23: Kitchen | E23: KTC Kitchen | G23: =VLOOKUP(B23,'Production Kitchen'!$B$5:$L$1029,10,FALSE) -> 2959 | I23: 1 | J23: gr | K23: =G23/I23 -> 2959 | R23: Internet | V23: Hot Chocolate | W23: M0017 | AC23: Sasakala Coffee | AD23: Dadang | AF23: 082240047008 | AG23: Supplier
A24: =A23+1 -> 18 | B24: Ktc Pro Macaroni Boiled | C24: P18 | D24: Kitchen | E24: KTC Kitchen | G24: =VLOOKUP(B24,'Production Kitchen'!$B$5:$L$1029,10,FALSE) -> 1593.8513 | I24: 1 | J24: gr | K24: =G24/I24 -> 1593.8513 | R24: Gas | V24: Iced Chocolate | W24: M0018 | AC24: Lingga Jaya Pack | AD24: Rohman | AF24: 082115563437 | AG24: Supplier
A25: =A24+1 -> 19 | B25: Ktc Pro Fettucini Boiled | C25: P19 | D25: Kitchen | E25: KTC Kitchen | G25: =VLOOKUP(B25,'Production Kitchen'!$B$5:$L$1029,10,FALSE) -> 1890.9279 | I25: 1 | J25: gr | K25: =G25/I25 -> 1890.9279 | R25: Kebersihan | V25: Choconutt Ice | W25: M0019 | AC25: Emergency Syrup | AD25: Denis | AF25: 081770555515 | AG25: Supplier
A26: =A25+1 -> 20 | B26: Ktc Pro Egg Wash | C26: P20 | D26: Kitchen | E26: KTC Kitchen | G26: =VLOOKUP(B26,'Production Kitchen'!$B$5:$L$1029,10,FALSE) -> 5.3734893 | I26: 1 | J26: gr | K26: =G26/I26 -> 5.3734893 | R26: Keamanan | V26: Naga Black Tea Hot | W26: M0020 | AC26: Ade Widya Plastik Cikutra | AF26: 082121297077 | AG26: Distributor
A27: =A26+1 -> 21 | B27: Ktc Pro Wings Marinate | C27: P21 | D27: Kitchen | E27: KTC Kitchen | G27: =VLOOKUP(B27,'Production Kitchen'!$B$5:$L$1029,10,FALSE) -> 8819.8396 | I27: 1 | J27: Porsi | K27: =G27/I27 -> 8819.8396 | R27: Service Listrik | V27: Naga Black Tea Ice | W27: M0021 | AC27: Kartu Empat Dimensi | AF27: 089528832388 | AG27: Distributor
A28: =A27+1 -> 22 | B28: Ktc Pro Concase | C28: P22 | D28: Kitchen | E28: KTC Kitchen | G28: =VLOOKUP(B28,'Production Kitchen'!$B$5:$L$1029,10,FALSE) -> 500.46874 | I28: 1 | J28: gr | K28: =G28/I28 -> 500.46874 | R28: Peralatan | V28: Thai Tea Hot | W28: M0022 | AC28: My Packaging | Tokopedia | AE28: link Tokped | AG28: Distributor
A29: =A28+1 -> 23 | B29: Ktc Pro Spaghetti Boiled | C29: P23 | D29: Kitchen | E29: KTC Kitchen | G29: =VLOOKUP(B29,'Production Kitchen'!$B$5:$L$1029,10,FALSE) -> 1601.7222 | I29: 1 | J29: gr/pcs | K29: =G29/I29 -> 1601.7222 | R29: OP Lain-lain | V29: Thai Tea Ice | W29: M0023 | AC29: Adijaya Mozzarella | AD29: Lala | AF29: 089530715802 | AG29: Supplier
A30: =A29+1 -> 24 | B30: Ktc Pro Rice | C30: P24 | D30: Kitchen | E30: KTC Kitchen | G30: =VLOOKUP(B30,'Production Kitchen'!$B$5:$L$1029,10,FALSE) -> 1093.9891 | I30: 1 | J30: Porsi | K30: =G30/I30 -> 1093.9891 | R30: Mutasi | T30: - | V30: Premium Tea Hot | W30: M0024 | AC30: Distributor Daging Pasar Cihapit | AD30: Tono | AF30: 081394412566 | AG30: Distributor
A31: =A30+1 -> 25 | B31: Ktc Pro Ayam Suwir | C31: P25 | D31: Kitchen | E31: KTC Kitchen | G31: =VLOOKUP(B31,'Production Kitchen'!$B$5:$L$1029,10,FALSE) -> 1114.5895 | I31: 1 | J31: gr | K31: =G31/I31 -> 1114.5895 | R31: KOL | V31: Taro Latte Hot | W31: M0025 | AC31: PD Aroma Jaya | AD31: Andri | AF31: 08882234984 | AG31: Distributor
A32: =A31+1 -> 26 | B32: KTC Pro Bumbu Magic | C32: P26 | D32: Kitchen | E32: KTC Kitchen | G32: =VLOOKUP(B32,'Production Kitchen'!$B$5:$L$1029,10,FALSE) -> 58.9875 | I32: 1 | J32: Porsi | K32: =G32/I32 -> 58.9875 | R32: Online Marketing | V32: Taro Latte Ice | W32: M0026 | AC32: Limas Raga Inti | AF32: 082121210600 | AG32: Distributor | AH32: gas
A33: =A32+1 -> 27 | B33: Ktc Pro Katsu Chicken | C33: P27 | D33: Kitchen | E33: KTC Kitchen | G33: =VLOOKUP(B33,'Production Kitchen'!$B$5:$L$1029,10,FALSE) -> 4805.2125 | I33: 1 | J33: gr | K33: =G33/I33 -> 4805.2125 | R33: Offline Marketing | V33: Matcha Latte Hot | W33: M0027 | AC33: B5 Coffee & Roastery | AE33: Jl.Bangbayang No.5 Dago Bandung | AF33: 081321534165 | AG33: Distributor
A34: =A33+1 -> 28 | B34: KTC Pro Scrumble Egg | C34: P28 | D34: Kitchen | E34: KTC Kitchen | G34: =VLOOKUP(B34,'Production Kitchen'!$B$5:$L$1029,10,FALSE) -> 2570.7587 | I34: 1 | J34: gr/pcs | K34: =G34/I34 -> 2570.7587 | R34: Renovasi & Furniture | V34: Matcha Latte Ice | W34: M0028 | AC34: Toko PD Cihapit | AG34: Direct
A35: =A34+1 -> 29 | B35: Ktc Pro Mushroom Crispy | C35: P29 | D35: Kitchen | E35: KTC Kitchen | G35: =VLOOKUP(B35,'Production Kitchen'!$B$5:$L$1029,10,FALSE) -> 6194.8333 | I35: 1 | J35: gr/pcs | K35: =G35/I35 -> 6194.8333 | R35: Piutang Karyawan | V35: Red Velvet Hot | W35: M0029 | AC35: Bara Gas | AG35: Direct
A36: =A35+1 -> 30 | B36: KTC Pro Mix Vegetable | C36: P30 | D36: Kitchen | E36: KTC Kitchen | G36: =VLOOKUP(B36,'Production Kitchen'!$B$5:$L$1029,10,FALSE) -> 864.65116 | I36: 1 | J36: gr/pcs | K36: =G36/I36 -> 864.65116 | R36: Hutang | V36: Red Velvet Ice | W36: M0030 | AC36: Borma | AG36: Direct
A37: =A36+1 -> 31 | B37: Ktc Pro Chicken Cordon Bleu | C37: P31 | D37: Kitchen | E37: KTC Kitchen | G37: =VLOOKUP(B37,'Production Kitchen'!$B$5:$L$1029,10,FALSE) -> 5399.9 | I37: 1 | J37: gr/pcs | K37: =G37/I37 -> 5399.9 | R37: Perlengkapan | V37: Lemon Squash | W37: M0031 | AC37: Pasar Cihapit | AG37: Direct
A38: =A37+1 -> 32 | B38: KTC Bumbu Oles Sate | C38: P32 | D38: Kitchen | E38: KTC Kitchen | G38: =VLOOKUP(B38,'Production Kitchen'!$B$5:$L$1029,10,FALSE) -> 65.385653 | I38: 1 | J38: pcs | K38: =G38/I38 -> 65.385653 | R38: Investasi | V38: Orange Squash | W38: M0032 | AC38: Setiabudi Market | AG38: Direct
A39: =A38+1 -> 33 | B39: KTC Pro Mix Platters | C39: P33 | D39: Kitchen | E39: KTC Kitchen | G39: =VLOOKUP(B39,'Production Kitchen'!$B$5:$L$1029,10,FALSE) -> 8481 | I39: 1 | J39: pcs | K39: =G39/I39 -> 8481 | R39: Sewa | V39: Mineral Water | W39: M0033 | AC39: Putra Asmi, Dago | AG39: Direct
A40: =A39+1 -> 34 | B40: KTC Pro Bumbu Bakar Oles | C40: P34 | D40: Kitchen | E40: KTC Kitchen | G40: =VLOOKUP(B40,'Production Kitchen'!$B$5:$L$1029,10,FALSE) -> 766.22625 | I40: 1 | J40: pcs | K40: =G40/I40 -> 766.22625 | R40: - | V40: Karma Coffee | W40: M0034 | AC40: RSB, Dago | AG40: Direct
A41: =A40+1 -> 35 | B41: KTC Pro Tempe Ungkep | C41: P35 | D41: Kitchen | E41: KTC Kitchen | G41: =VLOOKUP(B41,'Production Kitchen'!$B$5:$L$1029,10,FALSE) -> 275 | I41: 1 | J41: pcs | K41: =G41/I41 -> 275 | V41: Soko Mint | W41: M0035 | AC41: Shopee | AG41: Direct
...

Sheet Kesimpulan Menu
A1: The Soko Coffee Tea Chocolate
I2: =AVERAGE(I6:I176) -> #N/A | J2: 0.36 | K2: 1 | L2: 0.2 | N2: 0.38
H3: Dine In | K3: Online Delivery
A4: No | B4: Divisi | C4: Kategori | D4: Menu | F4: Kode | G4: HPP Net | H4: Harga Jual | I4: Margin Cost % | J4: Checker | K4: Target Price | L4: Merch Cost | M4: Margin Cost % | N4: Checker | O4: Harga Awal | P4: Description | Q4: Deskripsi | R4: Keterangan | S4: Fix Online
A5: 1 | B5: Bar | C5: Coffee | D5: Es Kopi Soko | F5: =VLOOKUP(D5,Master!$V$7:$W$1000,2,FALSE) -> M0015 | G5: =VLOOKUP(D5,'Menu Bar'!$B$6:$I$1948,8,FALSE) -> 8309.2542 | H5: 26000 | I5: =G5/H5 -> 0.3195867 | J5: =IF(I5<=$J$2,"Good Price","Bad Price") -> Good Price | K5: =1000+H5 -> 27000 | L5: =K5*$L$2 -> 5400 | M5: =G5/(K5-L5) -> 0.38468769 | N5: =IF(M5<=$N$2,"Good Price","Bad Price") -> Bad Price | O5: 27000 | Q5: kopi espresso di atasnya dengan susu panas atau krim berbusa dan sering dibumbui dengan kayu manis
A6: =A5+1 -> 2 | B6: Bar | C6: Coffee | D6: Cappucino Ice | F6: =VLOOKUP(D6,Master!$V$7:$W$1000,2,FALSE) -> M0002 | G6: =VLOOKUP(D6,'Menu Bar'!$B$6:$I$1948,8,FALSE) -> 6735.6121 | H6: 26000 | I6: =G6/H6 -> 0.25906201 | J6: =IF(I6<=$J$2,"Good Price","Bad Price") -> Good Price | K6: =1000+H6 -> 27000 | L6: =K6*$L$2 -> 5400 | M6: =G6/(K6-L6) -> 0.3118339 | N6: =IF(M6<=$N$2,"Good Price","Bad Price") -> Good Price
A7: =A6+1 -> 3 | B7: Bar | C7: Coffee | D7: Cappucino Hot | F7: =VLOOKUP(D7,Master!$V$7:$W$1000,2,FALSE) -> M0001 | G7: =VLOOKUP(D7,'Menu Bar'!$B$6:$I$1948,8,FALSE) -> 7222.6053 | H7: 24000 | I7: =G7/H7 -> 0.30094189 | J7: =IF(I7<=$J$2,"Good Price","Bad Price") -> Good Price | K7: =1000+H7 -> 25000 | L7: =K7*$L$2 -> 5000 | M7: =G7/(K7-L7) -> 0.36113026 | N7: =IF(M7<=$N$2,"Good Price","Bad Price") -> Good Price
A8: =A7+1 -> 4 | B8: Bar | C8: Coffee | D8: Iced Cafe Latte | F8: =VLOOKUP(D8,Master!$V$7:$W$1000,2,FALSE) -> M0003 | G8: =VLOOKUP(D8,'Menu Bar'!$B$6:$I$1948,8,FALSE) -> 6408.2182 | H8: 26000 | I8: =G8/H8 -> 0.24646993 | J8: =IF(I8<=$J$2,"Good Price","Bad Price") -> Good Price | K8: =1000+H8 -> 27000 | L8: =K8*$L$2 -> 5400 | M8: =G8/(K8-L8) -> 0.29667677 | N8: =IF(M8<=$N$2,"Good Price","Bad Price") -> Good Price
A9: =A8+1 -> 5 | B9: Bar | C9: Coffee | D9: Hot Cafe Latte | F9: =VLOOKUP(D9,Master!$V$7:$W$1000,2,FALSE) -> M0004 | G9: =VLOOKUP(D9,'Menu Bar'!$B$6:$I$1948,8,FALSE) -> 7885.5863 | H9: 24000 | I9: =G9/H9 -> 0.3285661 | J9: =IF(I9<=$J$2,"Good Price","Bad Price") -> Good Price | K9: =1000+H9 -> 25000 | L9: =K9*$L$2 -> 5000 | M9: =G9/(K9-L9) -> 0.39427932 | N9: =IF(M9<=$N$2,"Good Price","Bad Price") -> Bad Price
A10: =A9+1 -> 6 | B10: Bar | C10: Coffee | D10: Iced Americano | E10: Black Coffee Ice | F10: =VLOOKUP(D10,Master!$V$7:$W$1000,2,FALSE) -> M0006 | G10: =VLOOKUP(D10,'Menu Bar'!$B$6:$I$1948,8,FALSE) -> 4483.9474 | H10: 24000 | I10: =G10/H10 -> 0.18683114 | J10: =IF(I10<=$J$2,"Good Price","Bad Price") -> Good Price | K10: =1000+H10 -> 25000 | L10: =K10*$L$2 -> 5000 | M10: =G10/(K10-L10) -> 0.22419737 | N10: =IF(M10<=$N$2,"Good Price","Bad Price") -> Good Price
A11: =A10+1 -> 7 | B11: Bar | C11: Coffee | D11: Hot Americano | E11: Black Coffee Hot | F11: =VLOOKUP(D11,Master!$V$7:$W$1000,2,FALSE) -> M0005 | G11: =VLOOKUP(D11,'Menu Bar'!$B$6:$I$1948,8,FALSE) -> 4756.7632 | H11: 22000 | I11: =G11/H11 -> 0.21621651 | J11: =IF(I11<=$J$2,"Good Price","Bad Price") -> Good Price | K11: =1000+H11 -> 23000 | L11: =K11*$L$2 -> 4600 | M11: =G11/(K11-L11) -> 0.25851974 | N11: =IF(M11<=$N$2,"Good Price","Bad Price") -> Good Price
A12: =A11+1 -> 8 | B12: Bar | C12: Coffee | D12: Hot Vietnam Drip | E12: Vietnam Drip Ice 26K | F12: =VLOOKUP(D12,Master!$V$7:$W$1000,2,FALSE) -> M0043 | G12: =VLOOKUP(D12,'Menu Bar'!$B$6:$I$1948,8,FALSE) -> 5875.6821 | H12: 24000 | I12: =G12/H12 -> 0.24482009 | J12: =IF(I12<=$J$2,"Good Price","Bad Price") -> Good Price | K12: =1000+H12 -> 25000 | L12: =K12*$L$2 -> 5000 | M12: =G12/(K12-L12) -> 0.2937841 | N12: =IF(M12<=$N$2,"Good Price","Bad Price") -> Good Price
A13: =A12+1 -> 9 | B13: Bar | C13: Coffee | D13: Japanese Lokal | E13: Japanese | F13: =VLOOKUP(D13,Master!$V$7:$W$1000,2,FALSE) -> M0039 | G13: =VLOOKUP(D13,'Menu Bar'!$B$6:$I$1948,8,FALSE) -> 8806.5789 | H13: 27000 | I13: =G13/H13 -> 0.32616959 | J13: =IF(I13<=$J$2,"Good Price","Bad Price") -> Good Price | K13: 27000 | L13: =K13*$L$2 -> 5400 | M13: =G13/(K13-L13) -> 0.40771199 | N13: =IF(M13<=$N$2,"Good Price","Bad Price") -> Bad Price
A14: =A13+1 -> 10 | B14: Bar | C14: Coffee | D14: V60 Lokal | E14: V60 | F14: =VLOOKUP(D14,Master!$V$7:$W$1000,2,FALSE) -> M0038 | G14: =VLOOKUP(D14,'Menu Bar'!$B$6:$I$1948,8,FALSE) -> 8882.8421 | H14: 26000 | I14: =G14/H14 -> 0.34164777 | J14: =IF(I14<=$J$2,"Good Price","Bad Price") -> Good Price | K14: 26000 | L14: =K14*$L$2 -> 5200 | M14: =G14/(K14-L14) -> 0.42705972 | N14: =IF(M14<=$N$2,"Good Price","Bad Price") -> Bad Price
A15: =A14+1 -> 11 | B15: Bar | C15: Coffee | D15: Aeropress Lokal | E15: Aeropress | F15: =VLOOKUP(D15,Master!$V$7:$W$1000,2,FALSE) -> M0042 | G15: =VLOOKUP(D15,'Menu Bar'!$B$6:$I$1948,8,FALSE) -> 8423.1447 | H15: 28000 | I15: =G15/H15 -> 0.3008266 | J15: =IF(I15<=$J$2,"Good Price","Bad Price") -> Good Price | K15: 28000 | L15: =K15*$L$2 -> 5600 | M15: =G15/(K15-L15) -> 0.37603325 | N15: =IF(M15<=$N$2,"Good Price","Bad Price") -> Good Price
A16: =A15+1 -> 12 | B16: Bar | C16: Coffee | D16: Iced Vanilla Latte | F16: =VLOOKUP(D16,Master!$V$7:$W$1000,2,FALSE) -> M0012 | G16: =VLOOKUP(D16,'Menu Bar'!$B$6:$I$1948,8,FALSE) -> 9911.3061 | H16: 28000 | I16: =G16/H16 -> 0.35397522 | J16: =IF(I16<=$J$2,"Good Price","Bad Price") -> Good Price | K16: =1000+H16 -> 29000 | L16: =K16*$L$2 -> 5800 | M16: =G16/(K16-L16) -> 0.42721147 | N16: =IF(M16<=$N$2,"Good Price","Bad Price") -> Bad Price
A17: =A16+1 -> 13 | B17: Bar | C17: Coffee | D17: Hot Vanilla Latte | F17: =VLOOKUP(D17,Master!$V$7:$W$1000,2,FALSE) -> M0011 | G17: =VLOOKUP(D17,'Menu Bar'!$B$6:$I$1948,8,FALSE) -> 10070.586 | H17: 27000 | I17: =G17/H17 -> 0.37298468 | J17: =IF(I17<=$J$2,"Good Price","Bad Price") -> Bad Price | K17: =1000+H17 -> 28000 | L17: =K17*$L$2 -> 5600 | M17: =G17/(K17-L17) -> 0.44957975 | N17: =IF(M17<=$N$2,"Good Price","Bad Price") -> Bad Price
A18: =A17+1 -> 14 | B18: Bar | C18: Coffee | D18: Iced Caramel Latte | F18: =VLOOKUP(D18,Master!$V$7:$W$1000,2,FALSE) -> M0083 | G18: =VLOOKUP(D18,'Menu Bar'!$B$6:$I$1948,8,FALSE) -> 9911.3061 | H18: 28000 | I18: =G18/H18 -> 0.35397522 | J18: =IF(I18<=$J$2,"Good Price","Bad Price") -> Good Price | K18: =1000+H18 -> 29000 | L18: =K18*$L$2 -> 5800 | M18: =G18/(K18-L18) -> 0.42721147 | N18: =IF(M18<=$N$2,"Good Price","Bad Price") -> Bad Price
A19: =A18+1 -> 15 | B19: Bar | C19: Coffee | D19: Hot Caramel Latte | F19: =VLOOKUP(D19,Master!$V$7:$W$1000,2,FALSE) -> M0082 | G19: =VLOOKUP(D19,'Menu Bar'!$B$6:$I$1948,8,FALSE) -> 10070.586 | H19: 27000 | I19: =G19/H19 -> 0.37298468 | J19: =IF(I19<=$J$2,"Good Price","Bad Price") -> Bad Price | K19: =1000+H19 -> 28000 | L19: =K19*$L$2 -> 5600 | M19: =G19/(K19-L19) -> 0.44957975 | N19: =IF(M19<=$N$2,"Good Price","Bad Price") -> Bad Price
A20: =A19+1 -> 16 | B20: Bar | C20: Coffee | D20: Hazelnut Latte Ice | F20: =VLOOKUP(D20,Master!$V$7:$W$1000,2,FALSE) -> M0010 | G20: =VLOOKUP(D20,'Menu Bar'!$B$6:$I$1948,8,FALSE) -> 9911.3061 | H20: 28000 | I20: =G20/H20 -> 0.35397522 | J20: =IF(I20<=$J$2,"Good Price","Bad Price") -> Good Price | K20: =1000+H20 -> 29000 | L20: =K20*$L$2 -> 5800 | M20: =G20/(K20-L20) -> 0.42721147 | N20: =IF(M20<=$N$2,"Good Price","Bad Price") -> Bad Price
A21: =A20+1 -> 17 | B21: Bar | C21: Coffee | D21: Hazelnut Latte Hot | F21: =VLOOKUP(D21,Master!$V$7:$W$1000,2,FALSE) -> M0009 | G21: =VLOOKUP(D21,'Menu Bar'!$B$6:$I$1948,8,FALSE) -> 10070.586 | H21: 27000 | I21: =G21/H21 -> 0.37298468 | J21: =IF(I21<=$J$2,"Good Price","Bad Price") -> Bad Price | K21: =1000+H21 -> 28000 | L21: =K21*$L$2 -> 5600 | M21: =G21/(K21-L21) -> 0.44957975 | N21: =IF(M21<=$N$2,"Good Price","Bad Price") -> Bad Price
A22: =A21+1 -> 18 | B22: Bar | C22: Coffee | D22: Butterscotch Latte Ice | F22: =VLOOKUP(D22,Master!$V$7:$W$1000,2,FALSE) -> B031 | G22: =VLOOKUP(D22,'Menu Bar'!$B$6:$I$1948,8,FALSE) -> 9480.3797 | H22: 28000 | I22: =G22/H22 -> 0.33858499 | J22: =IF(I22<=$J$2,"Good Price","Bad Price") -> Good Price | K22: =1000+H22 -> 29000 | L22: =K22*$L$2 -> 5800 | M22: =G22/(K22-L22) -> 0.40863706 | N22: =IF(M22<=$N$2,"Good Price","Bad Price") -> Bad Price
A23: =A22+1 -> 19 | B23: Bar | C23: Coffee | D23: Butterscotch Latte Hot | F23: =VLOOKUP(D23,Master!$V$7:$W$1000,2,FALSE) -> B031 | G23: =VLOOKUP(D23,'Menu Bar'!$B$6:$I$1948,8,FALSE) -> 9566.7347 | H23: 27000 | I23: =G23/H23 -> 0.35432351 | J23: =IF(I23<=$J$2,"Good Price","Bad Price") -> Good Price | K23: =1000+H23 -> 28000 | L23: =K23*$L$2 -> 5600 | M23: =G23/(K23-L23) -> 0.42708637 | N23: =IF(M23<=$N$2,"Good Price","Bad Price") -> Bad Price
A24: =A23+1 -> 20 | B24: Bar | C24: Coffee | D24: Iced Moccacino | E24: Moccachino Ice | F24: =VLOOKUP(D24,Master!$V$7:$W$1000,2,FALSE) -> M0008 | G24: =VLOOKUP(D24,'Menu Bar'!$B$6:$I$1948,8,FALSE) -> 10792.973 | H24: 29000 | I24: =G24/H24 -> 0.37217147 | J24: =IF(I24<=$J$2,"Good Price","Bad Price") -> Bad Price | K24: =1000+H24 -> 30000 | L24: =K24*$L$2 -> 6000 | M24: =G24/(K24-L24) -> 0.4497072 | N24: =IF(M24<=$N$2,"Good Price","Bad Price") -> Bad Price
A25: =A24+1 -> 21 | B25: Bar | C25: Coffee | D25: Hot Moccacino | E25: Moccachino Hot | F25: =VLOOKUP(D25,Master!$V$7:$W$1000,2,FALSE) -> M0007 | G25: =VLOOKUP(D25,'Menu Bar'!$B$6:$I$1948,8,FALSE) -> 7555.7179 | H25: 27000 | I25: =G25/H25 -> 0.2798414 | J25: =IF(I25<=$J$2,"Good Price","Bad Price") -> Good Price | K25: =1000+H25 -> 28000 | L25: =K25*$L$2 -> 5600 | M25: =G25/(K25-L25) -> 0.33730883 | N25: =IF(M25<=$N$2,"Good Price","Bad Price") -> Good Price
A26: =A25+1 -> 22 | B26: Bar | C26: Milk Base | D26: Choco Java Ice | E26: Chocolate Java Ice | F26: =VLOOKUP(D26,Master!$V$7:$W$1000,2,FALSE) -> M0086 | G26: =VLOOKUP(D26,'Menu Bar'!$B$6:$I$1948,8,FALSE) -> 8937.0378 | H26: 26000 | I26: =G26/H26 -> 0.34373222 | J26: =IF(I26<=$J$2,"Good Price","Bad Price") -> Good Price | K26: =1000+H26 -> 27000 | L26: =K26*$L$2 -> 5400 | M26: =G26/(K26-L26) -> 0.41375175 | N26: =IF(M26<=$N$2,"Good Price","Bad Price") -> Bad Price
A27: =A26+1 -> 23 | B27: Bar | C27: Milk Base | D27: Choco Java Hot | E27: Chocolate Java Hot | F27: =VLOOKUP(D27,Master!$V$7:$W$1000,2,FALSE) -> M0087 | G27: =VLOOKUP(D27,'Menu Bar'!$B$6:$I$1948,8,FALSE) -> 8881.6316 | H27: 24000 | I27: =G27/H27 -> 0.37006798 | J27: =IF(I27<=$J$2,"Good Price","Bad Price") -> Bad Price | K27: =1000+H27 -> 25000 | L27: =K27*$L$2 -> 5000 | M27: =G27/(K27-L27) -> 0.44408158 | N27: =IF(M27<=$N$2,"Good Price","Bad Price") -> Bad Price
A28: =A27+1 -> 24 | B28: Bar | C28: Milk Base | D28: Dark Choco Ice | F28: =VLOOKUP(D28,Master!$V$7:$W$1000,2,FALSE) -> B013 | G28: =VLOOKUP(D28,'Menu Bar'!$B$6:$I$1948,8,FALSE) -> 7347.5368 | H28: 26000 | I28: =G28/H28 -> 0.28259757 | J28: =IF(I28<=$J$2,"Good Price","Bad Price") -> Good Price | K28: =1000+H28 -> 27000 | L28: =K28*$L$2 -> 5400 | M28: =G28/(K28-L28) -> 0.34016374 | N28: =IF(M28<=$N$2,"Good Price","Bad Price") -> Good Price
A29: =A28+1 -> 25 | B29: Bar | C29: Milk Base | D29: Dark Choco Hot | F29: =VLOOKUP(D29,Master!$V$7:$W$1000,2,FALSE) -> B037 | G29: =VLOOKUP(D29,'Menu Bar'!$B$6:$I$1948,8,FALSE) -> 6137.5368 | H29: 24000 | I29: =G29/H29 -> 0.2557307 | J29: =IF(I29<=$J$2,"Good Price","Bad Price") -> Good Price | K29: =1000+H29 -> 25000 | L29: =K29*$L$2 -> 5000 | M29: =G29/(K29-L29) -> 0.30687684 | N29: =IF(M29<=$N$2,"Good Price","Bad Price") -> Good Price
A30: =A29+1 -> 26 | B30: Bar | C30: Milk Base | D30: Matcha Latte Ice | F30: =VLOOKUP(D30,Master!$V$7:$W$1000,2,FALSE) -> M0028 | G30: =VLOOKUP(D30,'Menu Bar'!$B$6:$I$1948,8,FALSE) -> 8454.0378 | H30: 26000 | I30: =G30/H30 -> 0.3251553 | J30: =IF(I30<=$J$2,"Good Price","Bad Price") -> Good Price | K30: =1000+H30 -> 27000 | L30: =K30*$L$2 -> 5400 | M30: =G30/(K30-L30) -> 0.39139064 | N30: =IF(M30<=$N$2,"Good Price","Bad Price") -> Bad Price
A31: =A30+1 -> 27 | B31: Bar | C31: Milk Base | D31: Matcha Latte Hot | F31: =VLOOKUP(D31,Master!$V$7:$W$1000,2,FALSE) -> M0027 | G31: =VLOOKUP(D31,'Menu Bar'!$B$6:$I$1948,8,FALSE) -> 8881.6316 | H31: 24000 | I31: =G31/H31 -> 0.37006798 | J31: =IF(I31<=$J$2,"Good Price","Bad Price") -> Bad Price | K31: =1000+H31 -> 25000 | L31: =K31*$L$2 -> 5000 | M31: =G31/(K31-L31) -> 0.44408158 | N31: =IF(M31<=$N$2,"Good Price","Bad Price") -> Bad Price
A32: =A31+1 -> 28 | B32: Bar | C32: Milk Base | D32: Taro Latte Ice | F32: =VLOOKUP(D32,Master!$V$7:$W$1000,2,FALSE) -> M0026 | G32: =VLOOKUP(D32,'Menu Bar'!$B$6:$I$1948,8,FALSE) -> 7327.0378 | H32: 26000 | I32: =G32/H32 -> 0.28180915 | J32: =IF(I32<=$J$2,"Good Price","Bad Price") -> Good Price | K32: =1000+H32 -> 27000 | L32: =K32*$L$2 -> 5400 | M32: =G32/(K32-L32) -> 0.33921472 | N32: =IF(M32<=$N$2,"Good Price","Bad Price") -> Good Price
A33: =A32+1 -> 29 | B33: Bar | C33: Milk Base | D33: Taro Latte Hot | F33: =VLOOKUP(D33,Master!$V$7:$W$1000,2,FALSE) -> M0025 | G33: =VLOOKUP(D33,'Menu Bar'!$B$6:$I$1948,8,FALSE) -> 7271.6316 | H33: 24000 | I33: =G33/H33 -> 0.30298465 | J33: =IF(I33<=$J$2,"Good Price","Bad Price") -> Good Price | K33: =1000+H33 -> 25000 | L33: =K33*$L$2 -> 5000 | M33: =G33/(K33-L33) -> 0.36358158 | N33: =IF(M33<=$N$2,"Good Price","Bad Price") -> Good Price
A34: =A33+1 -> 30 | B34: Bar | C34: Milk Base | D34: Charcoal Latte Ice | F34: =VLOOKUP(D34,Master!$V$7:$W$1000,2,FALSE) -> M0048 | G34: =VLOOKUP(D34,'Menu Bar'!$B$6:$I$1948,8,FALSE) -> 6348.471 | H34: 26000 | I34: =G34/H34 -> 0.24417196 | J34: =IF(I34<=$J$2,"Good Price","Bad Price") -> Good Price | K34: =1000+H34 -> 27000 | L34: =K34*$L$2 -> 5400 | M34: =G34/(K34-L34) -> 0.29391069 | N34: =IF(M34<=$N$2,"Good Price","Bad Price") -> Good Price
A35: =A34+1 -> 31 | B35: Bar | C35: Milk Base | D35: Charcoal Latte Hot | F35: =VLOOKUP(D35,Master!$V$7:$W$1000,2,FALSE) -> M0056 | G35: =VLOOKUP(D35,'Menu Bar'!$B$6:$I$1948,8,FALSE) -> 6229.4737 | H35: 24000 | I35: =G35/H35 -> 0.2595614 | J35: =IF(I35<=$J$2,"Good Price","Bad Price") -> Good Price | K35: =1000+H35 -> 25000 | L35: =K35*$L$2 -> 5000 | M35: =G35/(K35-L35) -> 0.31147368 | N35: =IF(M35<=$N$2,"Good Price","Bad Price") -> Good Price
A36: =A35+1 -> 32 | B36: Bar | C36: Milk Base | D36: Tiramisu Latte Ice | E36: Tiramisu Coffee Ice | F36: =VLOOKUP(D36,Master!$V$7:$W$1000,2,FALSE) -> B005 | G36: =VLOOKUP(D36,'Menu Bar'!$B$6:$I$1948,8,FALSE) -> 10187.605 | H36: 28000 | I36: =G36/H36 -> 0.36384304 | J36: =IF(I36<=$J$2,"Good Price","Bad Price") -> Bad Price | K36: =1000+H36 -> 29000 | L36: =K36*$L$2 -> 5800 | M36: =G36/(K36-L36) -> 0.43912091 | N36: =IF(M36<=$N$2,"Good Price","Bad Price") -> Bad Price
A37: =A36+1 -> 33 | B37: Bar | C37: Milk Base | D37: Tiramisu Latte Hot | E37: Tiramisu Coffee Hot | F37: =VLOOKUP(D37,Master!$V$7:$W$1000,2,FALSE) -> B006 | G37: =VLOOKUP(D37,'Menu Bar'!$B$6:$I$1948,8,FALSE) -> 9006.7768 | H37: 27000 | I37: =G37/H37 -> 0.33358433 | J37: =IF(I37<=$J$2,"Good Price","Bad Price") -> Good Price | K37: =1000+H37 -> 28000 | L37: =K37*$L$2 -> 5600 | M37: =G37/(K37-L37) -> 0.40208825 | N37: =IF(M37<=$N$2,"Good Price","Bad Price") -> Bad Price
A38: =A37+1 -> 34 | B38: Bar | C38: Milk Base | D38: Red Velvet Ice | F38: =VLOOKUP(D38,Master!$V$7:$W$1000,2,FALSE) -> M0030 | G38: =VLOOKUP(D38,'Menu Bar'!$B$6:$I$1948,8,FALSE) -> 7327.0378 | H38: 26000 | I38: =G38/H38 -> 0.28180915 | J38: =IF(I38<=$J$2,"Good Price","Bad Price") -> Good Price | K38: =1000+H38 -> 27000 | L38: =K38*$L$2 -> 5400 | M38: =G38/(K38-L38) -> 0.33921472 | N38: =IF(M38<=$N$2,"Good Price","Bad Price") -> Good Price
A39: =A38+1 -> 35 | B39: Bar | C39: Milk Base | D39: Red Velvet Hot | F39: =VLOOKUP(D39,Master!$V$7:$W$1000,2,FALSE) -> M0029 | G39: =VLOOKUP(D39,'Menu Bar'!$B$6:$I$1948,8,FALSE) -> 7271.6316 | H39: 24000 | I39: =G39/H39 -> 0.30298465 | J39: =IF(I39<=$J$2,"Good Price","Bad Price") -> Good Price | K39: =1000+H39 -> 25000 | L39: =K39*$L$2 -> 5000 | M39: =G39/(K39-L39) -> 0.36358158 | N39: =IF(M39<=$N$2,"Good Price","Bad Price") -> Good Price
A40: =A39+1 -> 36 | B40: Bar | C40: Coffee | D40: Affogato | F40: =VLOOKUP(D40,Master!$V$7:$W$1000,2,FALSE) -> M0013 | G40: =VLOOKUP(D40,'Menu Bar'!$B$6:$I$1948,8,FALSE) -> 6528.4047 | H40: 26000 | I40: =G40/H40 -> 0.25109249 | J40: =IF(I40<=$J$2,"Good Price","Bad Price") -> Good Price | K40: 26000 | L40: =K40*$L$2 -> 5200 | M40: =G40/(K40-L40) -> 0.31386561 | N40: =IF(M40<=$N$2,"Good Price","Bad Price") -> Good Price
...

Sheet Menu Kitchen
A1: Resep Menu Kitchen
A2: The Soko Coffee Tea Chocolate
A5: Kode | B5: Menu | C5: Bahan | D5: Recipe QTY | E5: Satuan | F5: Hrg. Satuan | G5: HPP | H5: OH. Cost | I5: HPP Net | J5: Checker | K5: Ket
A6: =VLOOKUP(B6,Master!$V$7:$W$150,2,FALSE) -> M0049 | B6: Tahu Lada Garam | G6: =SUM(G7:G18) -> 4425.65 | H6: 0.1 | I6: =G6+(G6*H6) -> 4868.215 | J6: FALSE | K6: FALSE
C7: Tahu | D7: 3 | E7: =VLOOKUP(C7,Master!$B$6:$N$1000,9,FALSE) -> unit | F7: =VLOOKUP(C7,Master!$B$6:$N$1000,10,FALSE) -> 800 | G7: =D7*F7 -> 2400
C8: Cabe Rawit | D8: 5 | E8: =VLOOKUP(C8,Master!$B$6:$N$1000,9,FALSE) -> gr | F8: =VLOOKUP(C8,Master!$B$6:$N$1000,10,FALSE) -> 50 | G8: =D8*F8 -> 250
C9: Daun Bawang | D9: 3 | E9: =VLOOKUP(C9,Master!$B$6:$N$1000,9,FALSE) -> gr | F9: =VLOOKUP(C9,Master!$B$6:$N$1000,10,FALSE) -> 13 | G9: =D9*F9 -> 39
C10: Bawang Putih | D10: 2 | E10: =VLOOKUP(C10,Master!$B$6:$N$1000,9,FALSE) -> gr | F10: =VLOOKUP(C10,Master!$B$6:$N$1000,10,FALSE) -> 40 | G10: =D10*F10 -> 80
C11: Daun Jeruk | D11: 2 | E11: =VLOOKUP(C11,Master!$B$6:$N$1000,9,FALSE) -> gr | F11: =VLOOKUP(C11,Master!$B$6:$N$1000,10,FALSE) -> 64.2 | G11: =D11*F11 -> 128.4
C12: Cabe Merah Besar | D12: 4 | E12: =VLOOKUP(C12,Master!$B$6:$N$1000,9,FALSE) -> gr | F12: =VLOOKUP(C12,Master!$B$6:$N$1000,10,FALSE) -> 40 | G12: =D12*F12 -> 160
C13: Tepung | D13: 5 | E13: =VLOOKUP(C13,Master!$B$6:$N$1000,9,FALSE) -> gr | F13: =VLOOKUP(C13,Master!$B$6:$N$1000,10,FALSE) -> 14.25 | G13: =D13*F13 -> 71.25
C14: Powder Chicken | D14: 2 | E14: =VLOOKUP(C14,Master!$B$6:$N$1000,9,FALSE) -> gr | F14: =VLOOKUP(C14,Master!$B$6:$N$1000,10,FALSE) -> 38.5 | G14: =D14*F14 -> 77
C15: Merica | D15: 2 | E15: =VLOOKUP(C15,Master!$B$6:$N$1000,9,FALSE) -> gr | F15: =VLOOKUP(C15,Master!$B$6:$N$1000,10,FALSE) -> 90 | G15: =D15*F15 -> 180 | J15: cari barang subtitusi
C16: Lunch Box Ukuran M | D16: 1 | E16: =VLOOKUP(C16,Master!$B$6:$N$1000,9,FALSE) -> pcs | F16: =VLOOKUP(C16,Master!$B$6:$N$1000,10,FALSE) -> 1040 | G16: =D16*F16 -> 1040
A19: =VLOOKUP(B19,Master!$V$7:$W$150,2,FALSE) -> M0052 | B19: French Fries | G19: =SUM(G20:G25) -> 7503.2 | H19: 0.1 | I19: =G19+(G19*H19) -> 8253.52 | J19: FALSE | K19: FALSE
C20: Potato Cringkle Cut | D20: 150 | E20: =VLOOKUP(C20,Master!$B$6:$N$1000,9,FALSE) -> gr | F20: =VLOOKUP(C20,Master!$B$6:$N$1000,10,FALSE) -> 39.738 | G20: =D20*F20 -> 5960.7
C21: Powder Chicken | D21: 3 | E21: =VLOOKUP(C21,Master!$B$6:$N$1000,9,FALSE) -> gr | F21: =VLOOKUP(C21,Master!$B$6:$N$1000,10,FALSE) -> 38.5 | G21: =D21*F21 -> 115.5
C22: Chilli Sauce | D22: 10 | E22: =VLOOKUP(C22,Master!$B$6:$N$1000,9,FALSE) -> gr | F22: =VLOOKUP(C22,Master!$B$6:$N$1000,10,FALSE) -> 22.2 | G22: =D22*F22 -> 222
C23: Tomato | D23: 10 | E23: =VLOOKUP(C23,Master!$B$6:$N$1000,9,FALSE) -> gr | F23: =VLOOKUP(C23,Master!$B$6:$N$1000,10,FALSE) -> 16.5 | G23: =D23*F23 -> 165
C24: Lunch Box Ukuran M | D24: 1 | E24: =VLOOKUP(C24,Master!$B$6:$N$1000,9,FALSE) -> pcs | F24: =VLOOKUP(C24,Master!$B$6:$N$1000,10,FALSE) -> 1040 | G24: =D24*F24 -> 1040
A26: =VLOOKUP(B26,Master!$V$7:$W$150,2,FALSE) -> M0053 | B26: FF & Sausage Bratwurst | G26: =SUM(G27:G34) -> 8149.5167 | H26: 0.1 | I26: =G26+(G26*H26) -> 8964.4683 | J26: FALSE | K26: FALSE
C27: Potato Cringkle Cut | D27: 75 | E27: =VLOOKUP(C27,Master!$B$6:$N$1000,9,FALSE) -> gr | F27: =VLOOKUP(C27,Master!$B$6:$N$1000,10,FALSE) -> 39.738 | G27: =D27*F27 -> 2980.35
C28: Sosis | D28: 1 | E28: =VLOOKUP(C28,Master!$B$6:$N$1000,9,FALSE) -> pcs | F28: =VLOOKUP(C28,Master!$B$6:$N$1000,10,FALSE) -> 4666.6667 | G28: =D28*F28 -> 4666.6667
C29: Powder Chicken | D29: 3 | E29: =VLOOKUP(C29,Master!$B$6:$N$1000,9,FALSE) -> gr | F29: =VLOOKUP(C29,Master!$B$6:$N$1000,10,FALSE) -> 38.5 | G29: =D29*F29 -> 115.5
C30: Tomato | D30: 10 | E30: =VLOOKUP(C30,Master!$B$6:$N$1000,9,FALSE) -> gr | F30: =VLOOKUP(C30,Master!$B$6:$N$1000,10,FALSE) -> 16.5 | G30: =D30*F30 -> 165
C31: Chilli Sauce | D31: 10 | E31: =VLOOKUP(C31,Master!$B$6:$N$1000,9,FALSE) -> gr | F31: =VLOOKUP(C31,Master!$B$6:$N$1000,10,FALSE) -> 22.2 | G31: =D31*F31 -> 222
C32: Lunch Box Ukuran M | D32: 1 | E32: =VLOOKUP(C32,Master!$B$6:$N$1000,9,FALSE) -> pcs
A35: =VLOOKUP(B35,Master!$V$7:$W$150,2,FALSE) -> M0055 | B35: Aglio olio pasta Spaghetti | G35: =SUM(G36:G47) -> 7550.7222 | H35: 0.1 | I35: =G35+(G35*H35) -> 8305.7944 | J35: FALSE | K35: FALSE
C36: Ktc Pro Spaghetti Boiled | D36: 1 | E36: =VLOOKUP(C36,Master!$B$6:$N$1000,9,FALSE) -> gr/pcs | F36: =VLOOKUP(C36,Master!$B$6:$N$1000,10,FALSE) -> 1601.7222 | G36: =D36*F36 -> 1601.7222
C37: Smoked Beef | D37: 20 | E37: =VLOOKUP(C37,Master!$B$6:$N$1000,9,FALSE) -> gr | F37: =VLOOKUP(C37,Master!$B$6:$N$1000,10,FALSE) -> 86 | G37: =D37*F37 -> 1720
C38: Jamur Champignon | D38: 10 | E38: =VLOOKUP(C38,Master!$B$6:$N$1000,9,FALSE) -> gr | F38: =VLOOKUP(C38,Master!$B$6:$N$1000,10,FALSE) -> 45 | G38: =D38*F38 -> 450
C39: Bawang Bombay | D39: 5 | E39: =VLOOKUP(C39,Master!$B$6:$N$1000,9,FALSE) -> gr | F39: =VLOOKUP(C39,Master!$B$6:$N$1000,10,FALSE) -> 40 | G39: =D39*F39 -> 200
C40: Cabe Rawit | D40: 5 | E40: =VLOOKUP(C40,Master!$B$6:$N$1000,9,FALSE) -> gr | F40: =VLOOKUP(C40,Master!$B$6:$N$1000,10,FALSE) -> 50 | G40: =D40*F40 -> 250
C41: Bawang Putih | D41: 5 | E41: =VLOOKUP(C41,Master!$B$6:$N$1000,9,FALSE) -> gr | F41: =VLOOKUP(C41,Master!$B$6:$N$1000,10,FALSE) -> 40 | G41: =D41*F41 -> 200
C42: Cabe Merah Besar | D42: 5 | E42: =VLOOKUP(C42,Master!$B$6:$N$1000,9,FALSE) -> gr | F42: =VLOOKUP(C42,Master!$B$6:$N$1000,10,FALSE) -> 40 | G42: =D42*F42 -> 200
C43: Merica | D43: 2 | E43: =VLOOKUP(C43,Master!$B$6:$N$1000,9,FALSE) -> gr | F43: =VLOOKUP(C43,Master!$B$6:$N$1000,10,FALSE) -> 90 | G43: =D43*F43 -> 180
C44: Powder Chicken | D44: 2 | E44: =VLOOKUP(C44,Master!$B$6:$N$1000,9,FALSE) -> gr | F44: =VLOOKUP(C44,Master!$B$6:$N$1000,10,FALSE) -> 38.5 | G44: =D44*F44 -> 77
C45: Leaf Oregano | D45: 1 | E45: =VLOOKUP(C45,Master!$B$6:$N$1000,9,FALSE) -> gr | F45: =VLOOKUP(C45,Master!$B$6:$N$1000,10,FALSE) -> 280 | G45: =D45*F45 -> 280
C46: Tortilla Corn | D46: 0.8 | E46: =VLOOKUP(C46,Master!$B$6:$N$1000,9,FALSE) -> pcs | F46: =VLOOKUP(C46,Master!$B$6:$N$1000,10,FALSE) -> 1690 | G46: =D46*F46 -> 1352
C47: Lunch Box Ukuran M | D47: 1 | E47: =VLOOKUP(C47,Master!$B$6:$N$1000,9,FALSE) -> pcs | F47: =VLOOKUP(C47,Master!$B$6:$N$1000,10,FALSE) -> 1040 | G47: =D47*F47 -> 1040
...

Sheet Production Kitchen
A1: Resep Production Kitchen
A2: The Soko Coffee Tea Chocolate
B4: 1 | C4: 2 | D4: 3 | E4: 4 | F4: 5 | G4: 6 | H4: 7 | I4: 8 | J4: 9 | K4: 10 | L4: 11
A5: No | B5: Menu | C5: Bahan | D5: Recipe QTY | E5: Satuan | F5: Hrg. Satuan | G5: HPP | H5: OH. Cost | I5: HPP Net | J5: Portion | K5: Harga/Porsi | L5: Yield Portion
A6: 1 | B6: Ktc Pro Cream Soup | D6: =SUM(D7:D15) -> 175 | E6: ml | G6: =SUM(G7:G16) -> 5076.07 | H6: 0.1 | I6: =G6+(G6*H6) -> 5583.677 | J6: 1 | K6: =I6/J6 -> 5583.677 | L6: =D6/J6 -> 175
C7: Cooking Cream | D7: 30 | E7: =VLOOKUP(C7,Master!$B$6:$N$1000,9,FALSE) -> ml | F7: =VLOOKUP(C7,Master!B7:N337,10,FALSE) -> 66 | G7: =D7*F7 -> 1980
C8: UHT | D8: 120 | E8: =VLOOKUP(C8,Master!$B$6:$N$1000,9,FALSE) -> ml | F8: =VLOOKUP(C8,Master!$B$7:$N$1000,10,FALSE) -> 17.094333 | G8: =D8*F8 -> 2051.32
C9: Bawang Bombay | D9: 5 | E9: =VLOOKUP(C9,Master!$B$6:$N$1000,9,FALSE) -> gr | F9: =VLOOKUP(C9,Master!$B$7:$N$1000,10,FALSE) -> 40 | G9: =D9*F9 -> 200
C10: Air Galon | D10: 0 | E10: =VLOOKUP(C10,Master!$B$6:$N$1000,9,FALSE) -> ml | F10: =VLOOKUP(C10,Master!$B$7:$N$1000,10,FALSE) -> 0.66315789 | G10: =D10*F10 -> 0
C11: Tepung | D11: 3 | E11: =VLOOKUP(C11,Master!$B$6:$N$1000,9,FALSE) -> gr | F11: =VLOOKUP(C11,Master!$B$7:$N$1000,10,FALSE) -> 14.25 | G11: =D11*F11 -> 42.75
C12: Mentega Curah | D12: 3 | E12: =VLOOKUP(C12,Master!$B$6:$N$1000,9,FALSE) -> gr | F12: =VLOOKUP(C12,Master!$B$7:$N$1000,10,FALSE) -> 39 | G12: =D12*F12 -> 117
C13: Parsley | D13: 2 | E13: =VLOOKUP(C13,Master!$B$6:$N$1000,9,FALSE) -> gr | F13: =VLOOKUP(C13,Master!$B$7:$N$1000,10,FALSE) -> 60 | G13: =D13*F13 -> 120
C14: Powder Chicken | D14: 10 | E14: =VLOOKUP(C14,Master!$B$6:$N$1000,9,FALSE) -> gr | F14: =VLOOKUP(C14,Master!$B$7:$N$1000,10,FALSE) -> 38.5 | G14: =D14*F14 -> 385
C15: Merica | D15: 2 | E15: =VLOOKUP(C15,Master!$B$6:$N$1000,9,FALSE) -> gr | F15: =VLOOKUP(C15,Master!$B$7:$N$1000,10,FALSE) -> 90 | G15: =D15*F15 -> 180
A17: 2 | B17: Ktc Pro Sauce Blackpepper | D17: =SUM(D18:D27) -> 1947 | E17: =VLOOKUP(B17,Master!B6:N243,9,FALSE) -> gr/por | G17: =SUM(G18:G27) -> 37177.829 | H17: 0.1 | I17: =G17+(G17*H17) -> 40895.612 | J17: 30 | K17: =I17/J17 -> 1363.1871 | L17: =D17/J17 -> 64.9
C18: Bawang Putih | D18: 40 | E18: =VLOOKUP(C18,Master!$B$6:$N$260,9,FALSE) -> gr | F18: =VLOOKUP(C18,Master!$B$7:$N$309,10,FALSE) -> 40 | G18: =D18*F18 -> 1600
C19: Bawang Bombay | D19: 100 | E19: =VLOOKUP(C19,Master!$B$6:$N$243,9,FALSE) -> gr | F19: =VLOOKUP(C19,Master!$B$7:$N$309,10,FALSE) -> 40 | G19: =D19*F19 -> 4000
C20: Merica | D20: 5 | E20: =VLOOKUP(C20,Master!$B$6:$N$243,9,FALSE) -> gr | F20: =VLOOKUP(C20,Master!$B$7:$N$309,10,FALSE) -> 90 | G20: =D20*F20 -> 450
C21: Tomato | D21: 1000 | E21: =VLOOKUP(C21,Master!$B$6:$N$243,9,FALSE) -> gr | F21: =VLOOKUP(C21,Master!$B$7:$N$309,10,FALSE) -> 16.5 | G21: =D21*F21 -> 16500
C22: Lada Hitam Biji | D22: 25 | E22: =VLOOKUP(C22,Master!$B$6:$N$243,9,FALSE) -> gr | F22: =VLOOKUP(C22,Master!$B$7:$N$309,10,FALSE) -> 26 | G22: =D22*F22 -> 650
C23: Oyster Sauce Panda | D23: 150 | E23: =VLOOKUP(C23,Master!$B$6:$N$243,9,FALSE) -> gr | F23: =VLOOKUP(C23,Master!$B$7:$N$309,10,FALSE) -> 75 | G23: =D23*F23 -> 11250
C24: Gula Merah / Aren Padat Kiloan | D24: 105 | E24: =VLOOKUP(C24,Master!$B$6:$N$243,9,FALSE) -> gr | F24: =VLOOKUP(C24,Master!$B$7:$N$309,10,FALSE) -> 17 | G24: =D24*F24 -> 1785
C25: Kecap Manis | D25: 20 | E25: =VLOOKUP(C25,Master!$B$6:$N$243,9,FALSE) -> gr | F25: =VLOOKUP(C25,Master!$B$7:$N$309,10,FALSE) -> 29.0625 | G25: =D25*F25 -> 581.25
C26: Garam | D26: 2 | E26: =VLOOKUP(C26,Master!$B$6:$N$243,9,FALSE) -> gr | F26: =VLOOKUP(C26,Master!$B$7:$N$309,10,FALSE) -> 15 | G26: =D26*F26 -> 30
C27: Air Galon | D27: 500 | E27: =VLOOKUP(C27,Master!$B$6:$N$243,9,FALSE) -> ml | F27: =VLOOKUP(C27,Master!$B$7:$N$309,10,FALSE) -> 0.66315789 | G27: =D27*F27 -> 331.57895
A28: 3 | B28: Ktc Pro Pancake | D28: =SUM(D29:D35) -> 527 | E28: =VLOOKUP(B28,Master!B6:N243,9,FALSE) -> gr/slice | G28: =SUM(G29:G35) -> 15722.2 | H28: 0.1 | I28: =G28+(G28*H28) -> 17294.42 | J28: 3 | K28: =I28/J28 -> 5764.8067 | L28: =D28/J28 -> 175.66667
C29: Tepung | D29: 200 | E29: =VLOOKUP(C29,Master!$B$6:$N$1000,9,FALSE) -> gr | F29: =VLOOKUP(C29,Master!$B$7:$N$1000,10,FALSE) -> 14.25 | G29: =D29*F29 -> 2850
C30: Baking Powder | D30: 2 | E30: =VLOOKUP(C30,Master!$B$6:$N$1000,9,FALSE) -> gr | F30: =VLOOKUP(C30,Master!$B$7:$N$1000,10,FALSE) -> 148.33333 | G30: =D30*F30 -> 296.66667
C31: Soda Kue | D31: 2 | E31: =VLOOKUP(C31,Master!$B$6:$N$1000,9,FALSE) -> gr | F31: =VLOOKUP(C31,Master!$B$7:$N$1000,10,FALSE) -> 83.333333 | G31: =D31*F31 -> 166.66667
C32: Mentega Curah | D32: 60 | E32: =VLOOKUP(C32,Master!$B$6:$N$1000,9,FALSE) -> gr | F32: =VLOOKUP(C32,Master!$B$7:$N$1000,10,FALSE) -> 39 | G32: =D32*F32 -> 2340
C33: UHT | D33: 200 | E33: =VLOOKUP(C33,Master!$B$6:$N$1000,9,FALSE) -> ml | F33: =VLOOKUP(C33,Master!$B$7:$N$1000,10,FALSE) -> 17.094333 | G33: =D33*F33 -> 3418.8667
C34: Telur Ayam | D34: 3 | E34: =VLOOKUP(C34,Master!$B$6:$N$1000,9,FALSE) -> pcs | F34: =VLOOKUP(C34,Master!$B$7:$N$1000,10,FALSE) -> 1866.6667 | G34: =D34*F34 -> 5600
C35: Gula pasir | D35: 60 | E35: =VLOOKUP(C35,Master!$B$6:$N$1000,9,FALSE) -> gr | F35: =VLOOKUP(C35,Master!$B$7:$N$1000,10,FALSE) -> 17.5 | G35: =D35*F35 -> 1050
A37: 4 | B37: Ktc Pro Choco Lava | D37: =SUM(D38:D43) -> 408 | E37: =VLOOKUP(B37,Master!B6:N243,9,FALSE) -> gr/por | G37: =SUM(G38:G42) -> 22512.5 | H37: 0.1 | I37: =G37+(G37*H37) -> 24763.75 | J37: 5 | K37: =I37/J37 -> 4952.75 | L37: =D37/J37 -> 81.6
C38: Dark Chocolate | D38: 210 | E38: =VLOOKUP(C38,Master!$B$6:$N$1000,9,FALSE) -> gr | F38: =VLOOKUP(C38,Master!$B$7:$N$1000,10,FALSE) -> 56 | G38: =D38*F38 -> 11760
C39: Mentega Curah | D39: 90 | E39: =VLOOKUP(C39,Master!$B$6:$N$1000,9,FALSE) -> gr | F39: =VLOOKUP(C39,Master!$B$7:$N$1000,10,FALSE) -> 39 | G39: =D39*F39 -> 3510
C40: Tepung | D40: 60 | E40: =VLOOKUP(C40,Master!$B$6:$N$1000,9,FALSE) -> gr | F40: =VLOOKUP(C40,Master!$B$7:$N$1000,10,FALSE) -> 14.25 | G40: =D40*F40 -> 855
C41: Telur Ayam | D41: 3 | E41: =VLOOKUP(C41,Master!$B$6:$N$1000,9,FALSE) -> pcs | F41: =VLOOKUP(C41,Master!$B$7:$N$1000,10,FALSE) -> 1866.6667 | G41: =D41*F41 -> 5600
C42: Gula pasir | D42: 45 | E42: =VLOOKUP(C42,Master!$B$6:$N$1000,9,FALSE) -> gr | F42: =VLOOKUP(C42,Master!$B$7:$N$1000,10,FALSE) -> 17.5 | G42: =D42*F42 -> 787.5
A44: 5 | B44: Ktc Pro Sauce Barbeque | D44: =SUM(D45:D56) -> 1411.5 | E44: =VLOOKUP(B44,Master!B13:N250,9,FALSE) -> Porsi | G44: =SUM(G45:G57) -> 30774 | H44: 0.1 | I44: =G44+(G44*H44) -> 33851.4 | J44: 63 | K44: =I44/J44 -> 537.32381 | L44: =D44/J44 -> 22.404762
...

Sheet Menu Bar
A1: Resep Menu Bar
A2: The Soko Coffee Tea Chocolate
A5: Kode | B5: Menu | C5: Bahan | D5: Recipe QTY | E5: Satuan | F5: Hrg. Satuan | G5: HPP | H5: OH. Cost | I5: HPP Net | K5: Checker
A6: =VLOOKUP(B6,Master!$V$7:$W$150,2,FALSE) -> M0001 | B6: Cappucino Hot | G6: =SUM(G7:G10) -> 6280.5263 | H6: 0.15 | I6: =G6+(G6*H6) -> 7222.6053 | J6: TRUE | K6: TRUE
C7: Beans | D7: 18 | E7: =VLOOKUP(C7,Master!$B$6:$N$1000,9,FALSE) -> gr | F7: =VLOOKUP(C7,Master!$B$6:$N$1000,10,FALSE) -> 195 | G7: =D7*F7 -> 3510 | J7: split atau tidak?
C8: Air Galon | D8: 0 | E8: =VLOOKUP(C8,Master!$B$6:$N$1000,9,FALSE) -> ml | F8: =VLOOKUP(C8,Master!$B$6:$N$1000,10,FALSE) -> 0.66315789 | G8: =D8*F8 -> 0 | J8: Split
C9: Freshmilk | D9: 120 | E9: =VLOOKUP(C9,Master!$B$6:$N$1000,9,FALSE) -> ml | F9: =VLOOKUP(C9,Master!$B$6:$N$1000,10,FALSE) -> 18.421053 | G9: =D9*F9 -> 2210.5263
C10: Packing Cup Hot 8 Oz | D10: 1 | E10: =VLOOKUP(C10,Master!$B$6:$N$1000,9,FALSE) -> pcs | F10: =VLOOKUP(C10,Master!$B$6:$N$1000,10,FALSE) -> 560 | G10: =D10*F10 -> 560 | J10: cup ganti wrna
A11: =VLOOKUP(B11,Master!$V$7:$W$150,2,FALSE) -> M0002 | B11: Cappucino Ice | G11: =SUM(G12:G15) -> 5857.054 | H11: 0.15 | I11: =G11+(G11*H11) -> 6735.6121 | J11: TRUE | K11: TRUE
C12: Beans | D12: 18 | E12: =VLOOKUP(C12,Master!$B$6:$N$1000,9,FALSE) -> gr | F12: =VLOOKUP(C12,Master!$B$6:$N$1000,10,FALSE) -> 195 | G12: =D12*F12 -> 3510 | K12: CUT
C13: Bar Pro Simple Syrup | D13: 30 | E13: =VLOOKUP(C13,Master!$B$6:$N$1000,9,FALSE) -> ml | F13: =VLOOKUP(C13,Master!$B$6:$N$1000,10,FALSE) -> 15.983579 | G13: =D13*F13 -> 479.50737
C14: UHT | D14: 80 | E14: =VLOOKUP(C14,Master!$B$6:$N$1000,9,FALSE) -> ml | F14: =VLOOKUP(C14,Master!$B$6:$N$1000,10,FALSE) -> 17.094333 | G14: =D14*F14 -> 1367.5467
C15: Cup Oval 12 Oz Custom Soko | D15: 1 | E15: =VLOOKUP(C15,Master!$B$6:$N$1000,9,FALSE) -> pcs | F15: =VLOOKUP(C15,Master!$B$6:$N$1000,10,FALSE) -> 500 | G15: =D15*F15 -> 500 | J15: cup plastik ganti baru
A16: =VLOOKUP(B16,Master!$V$7:$W$150,2,FALSE) -> M0003 | B16: Iced Cafe Latte | G16: =SUM(G17:G20) -> 5572.3637 | H16: 0.15 | I16: =G16+(G16*H16) -> 6408.2182 | J16: TRUE | K16: TRUE
C17: Beans | D17: 18 | E17: =VLOOKUP(C17,Master!$B$6:$N$1000,9,FALSE) -> gr | F17: =VLOOKUP(C17,Master!$B$6:$N$1000,10,FALSE) -> 195 | G17: =D17*F17 -> 3510
C18: Air Galon | D18: 36 | E18: =VLOOKUP(C18,Master!$B$6:$N$1000,9,FALSE) -> ml | F18: =VLOOKUP(C18,Master!$B$6:$N$1000,10,FALSE) -> 0.66315789 | G18: =D18*F18 -> 23.873684
C19: UHT | D19: 90 | E19: =VLOOKUP(C19,Master!$B$6:$N$1000,9,FALSE) -> ml | F19: =VLOOKUP(C19,Master!$B$6:$N$1000,10,FALSE) -> 17.094333 | G19: =D19*F19 -> 1538.49
C20: Cup Oval 12 Oz Custom Soko | D20: 1 | E20: =VLOOKUP(C20,Master!$B$6:$N$1000,9,FALSE) -> pcs | F20: =VLOOKUP(C20,Master!$B$6:$N$1000,10,FALSE) -> 500 | G20: =D20*F20 -> 500
A21: =VLOOKUP(B21,Master!$V$7:$W$150,2,FALSE) -> M0004 | B21: Hot Cafe Latte | G21: =SUM(G22:G25) -> 6857.0316 | H21: 0.15 | I21: =G21+(G21*H21) -> 7885.5863 | J21: TRUE | K21: TRUE
C22: Beans | D22: 18 | E22: =VLOOKUP(C22,Master!$B$6:$N$1000,9,FALSE) -> gr | F22: =VLOOKUP(C22,Master!$B$6:$N$1000,10,FALSE) -> 195 | G22: =D22*F22 -> 3510 | J22: split atau tidak?
C23: Air Galon | D23: 36 | E23: =VLOOKUP(C23,Master!$B$6:$N$1000,9,FALSE) -> ml | F23: =VLOOKUP(C23,Master!$B$6:$N$1000,10,FALSE) -> 0.66315789 | G23: =D23*F23 -> 23.873684 | J23: Tidak di Split
C24: Freshmilk | D24: 150 | E24: =VLOOKUP(C24,Master!$B$6:$N$1000,9,FALSE) -> ml | F24: =VLOOKUP(C24,Master!$B$6:$N$1000,10,FALSE) -> 18.421053 | G24: =D24*F24 -> 2763.1579
C25: Packing Cup Hot 8 Oz | D25: 1 | E25: =VLOOKUP(C25,Master!$B$6:$N$1000,9,FALSE) -> pcs | F25: =VLOOKUP(C25,Master!$B$6:$N$1000,10,FALSE) -> 560 | G25: =D25*F25 -> 560
A26: =VLOOKUP(B26,Master!$V$7:$W$150,2,FALSE) -> M0005 | B26: Hot Americano | G26: =SUM(G27:G29) -> 4136.3158 | H26: 0.15 | I26: =G26+(G26*H26) -> 4756.7632 | J26: TRUE | K26: TRUE
C27: Beans | D27: 18 | E27: =VLOOKUP(C27,Master!$B$6:$N$1000,9,FALSE) -> gr | F27: =VLOOKUP(C27,Master!$B$6:$N$1000,10,FALSE) -> 195 | G27: =D27*F27 -> 3510
C28: Air Galon | D28: 100 | E28: =VLOOKUP(C28,Master!$B$6:$N$1000,9,FALSE) -> ml | F28: =VLOOKUP(C28,Master!$B$6:$N$1000,10,FALSE) -> 0.66315789 | G28: =D28*F28 -> 66.315789
C29: Packing Cup Hot 8 Oz | D29: 1 | E29: =VLOOKUP(C29,Master!$B$6:$N$1000,9,FALSE) -> pcs | F29: =VLOOKUP(C29,Master!$B$6:$N$1000,10,FALSE) -> 560 | G29: =D29*F29 -> 560
A30: =VLOOKUP(B30,Master!$V$7:$W$150,2,FALSE) -> M0006 | B30: Iced Americano | G30: =SUM(G31:G33) -> 4076.3158 | H30: 0.1 | I30: =G30+(G30*H30) -> 4483.9474 | J30: TRUE | K30: TRUE
C31: Beans | D31: 18 | E31: =VLOOKUP(C31,Master!$B$6:$N$1000,9,FALSE) -> gr | F31: =VLOOKUP(C31,Master!$B$6:$N$1000,10,FALSE) -> 195 | G31: =D31*F31 -> 3510
C32: Air Galon | D32: 100 | E32: =VLOOKUP(C32,Master!$B$6:$N$1000,9,FALSE) -> ml | F32: =VLOOKUP(C32,Master!$B$6:$N$1000,10,FALSE) -> 0.66315789 | G32: =D32*F32 -> 66.315789
C33: Cup Oval 12 Oz Custom Soko | D33: 1 | E33: =VLOOKUP(C33,Master!$B$6:$N$1000,9,FALSE) -> pcs | F33: =VLOOKUP(C33,Master!$B$6:$N$1000,10,FALSE) -> 500 | G33: =D33*F33 -> 500
A34: =VLOOKUP(B34,Master!$V$7:$W$150,2,FALSE) -> M0007 | B34: Hot Moccacino | G34: =SUM(G35:G39) -> 6570.1895 | H34: 0.15 | I34: =G34+(G34*H34) -> 7555.7179 | J34: TRUE | K34: TRUE
C35: Beans | D35: 18 | E35: =VLOOKUP(C35,Master!$B$6:$N$1000,9,FALSE) -> gr | F35: =VLOOKUP(C35,Master!$B$6:$N$1000,10,FALSE) -> 195 | G35: =D35*F35 -> 3510
C36: Air Galon | D36: 36 | E36: =VLOOKUP(C36,Master!$B$6:$N$1000,9,FALSE) -> ml | F36: =VLOOKUP(C36,Master!$B$6:$N$1000,10,FALSE) -> 0.66315789 | G36: =D36*F36 -> 23.873684
C37: Freshmilk | D37: 15 | E37: =VLOOKUP(C37,Master!$B$6:$N$1000,9,FALSE) -> ml | F37: =VLOOKUP(C37,Master!$B$6:$N$1000,10,FALSE) -> 18.421053 | G37: =D37*F37 -> 276.31579
C38: Powder Chocolate Origin Java Srawana | D38: 10 | E38: =VLOOKUP(C38,Master!$B$6:$N$1000,9,FALSE) -> gr | F38: =VLOOKUP(C38,Master!$B$6:$N$1000,10,FALSE) -> 220 | G38: =D38*F38 -> 2200
C39: Packing Cup Hot 8 Oz | D39: 1 | E39: =VLOOKUP(C39,Master!$B$6:$N$1000,9,FALSE) -> pcs | F39: =VLOOKUP(C39,Master!$B$6:$N$1000,10,FALSE) -> 560 | G39: =D39*F39 -> 560
A40: =VLOOKUP(B40,Master!$V$7:$W$150,2,FALSE) -> M0008 | B40: Iced Moccacino | G40: =SUM(G41:G45) -> 9385.1937 | H40: 0.15 | I40: =G40+(G40*H40) -> 10792.973 | J40: TRUE | K40: TRUE
C41: Beans | D41: 18 | E41: =VLOOKUP(C41,Master!$B$6:$N$1000,9,FALSE) -> gr | F41: =VLOOKUP(C41,Master!$B$6:$N$1000,10,FALSE) -> 195 | G41: =D41*F41 -> 3510
C42: Air Galon | D42: 36 | E42: =VLOOKUP(C42,Master!$B$6:$N$1000,9,FALSE) -> ml | F42: =VLOOKUP(C42,Master!$B$6:$N$1000,10,FALSE) -> 0.66315789 | G42: =D42*F42 -> 23.873684
...

Sheet Production Bar
A1: Resep Production Bar
A2: The Soko Coffee Tea Chocolate
B4: 1 | C4: 2 | D4: 3 | E4: 4 | F4: 5 | G4: 6 | H4: 7 | I4: 8 | J4: 9 | K4: 10 | L4: 11
A5: No | B5: Menu | C5: Bahan | D5: Recipe QTY | E5: Satuan | F5: Hrg. Satuan | G5: HPP | H5: OH. Cost | I5: HPP Net | J5: Portion | K5: Harga/Porsi | L5: Yield Portion
A6: 1 | B6: Bar Pro Chrysantemum | D6: =SUM(D7:D8) -> 253 | E6: =VLOOKUP(B6,Master!B6:N243,9,FALSE) -> gr/pcs | G6: =SUM(G7:G8) -> 5685.7895 | H6: 0.1 | I6: =G6+(G6*H6) -> 6254.3684 | J6: 200 | K6: =I6/J6 -> 31.271842 | L6: =D6/J6 -> 1.265
C7: Chrysantemum | D7: 3 | E7: =VLOOKUP(C7,Master!$B$6:$N$243,9,FALSE) -> gr | F7: =VLOOKUP(C7,Master!B6:N243,10,FALSE) -> 1840 | G7: =D7*F7 -> 5520
C8: Air Galon | D8: 250 | E8: =VLOOKUP(C8,Master!$B$6:$N$243,9,FALSE) -> ml | F8: =VLOOKUP(C8,Master!B7:N244,10,FALSE) -> 0.66315789 | G8: =D8*F8 -> 165.78947
A9: 2 | B9: Bar Pro Rosella | D9: =SUM(D10:D11) -> 255 | E9: =VLOOKUP(B9,Master!B9:N246,9,FALSE) -> gr/slice | G9: =SUM(G10:G11) -> 3165.7895 | H9: 0.1 | I9: =G9+(G9*H9) -> 3482.3684 | J9: 200 | K9: =I9/J9 -> 17.411842 | L9: =D9/J9 -> 1.275
C10: Rosella Tea | D10: 5 | E10: =VLOOKUP(C10,Master!$B$6:$N$243,9,FALSE) -> gr | F10: =VLOOKUP(C10,Master!B9:N246,10,FALSE) -> 600 | G10: =D10*F10 -> 3000
C11: Air Galon | D11: 250 | E11: =VLOOKUP(C11,Master!$B$6:$N$243,9,FALSE) -> ml | F11: =VLOOKUP(C11,Master!B10:N247,10,FALSE) -> 0.66315789 | G11: =D11*F11 -> 165.78947
A12: 3 | B12: Bar Pro Black Tea | D12: =SUM(D13:D14) -> 1022 | E12: =VLOOKUP(B12,Master!B12:N249,9,FALSE) -> ml | G12: =SUM(G13:G14) -> 2166.4912 | H12: 0.1 | I12: =G12+(G12*H12) -> 2383.1404 | J12: 2000 | K12: =I12/J12 -> 1.1915702 | L12: =D12/J12 -> 0.511
C13: Teh Naga | D13: 22 | E13: =VLOOKUP(C13,Master!$B$6:$N$243,9,FALSE) -> gr | F13: =VLOOKUP(C13,Master!B12:N249,10,FALSE) -> 68.333333 | G13: =D13*F13 -> 1503.3333
C14: Air Galon | D14: 1000 | E14: =VLOOKUP(C14,Master!$B$6:$N$243,9,FALSE) -> ml | F14: =VLOOKUP(C14,Master!B13:N250,10,FALSE) -> 0.66315789 | G14: =D14*F14 -> 663.15789
A15: 4 | B15: Bar Pro Cengkeh | D15: =SUM(D16:D17) -> 230 | E15: =VLOOKUP(B15,Master!B15:N252,9,FALSE) -> gr | G15: =SUM(G16:G17) -> 4339.2632 | H15: 0.1 | I15: =G15+(G15*H15) -> 4773.1895 | J15: 200 | K15: =I15/J15 -> 23.865947 | L15: =D15/J15 -> 1.15
C16: Cengkeh | D16: 20 | E16: =VLOOKUP(C16,Master!$B$6:$N$243,9,FALSE) -> gr | F16: =VLOOKUP(C16,Master!B15:N252,10,FALSE) -> 210 | G16: =D16*F16 -> 4200
C17: Air Galon | D17: 210 | E17: =VLOOKUP(C17,Master!$B$6:$N$243,9,FALSE) -> ml | F17: =VLOOKUP(C17,Master!B16:N253,10,FALSE) -> 0.66315789 | G17: =D17*F17 -> 139.26316
A18: 5 | B18: Bar Pro Mix SKM | D18: =SUM(D19:D20) -> 1220 | E18: =VLOOKUP(B18,Master!B18:N255,9,FALSE) -> ml | G18: =SUM(G19:G20) -> 45473.684 | H18: 0.1 | I18: =G18+(G18*H18) -> 50021.053 | J18: 1220 | K18: =I18/J18 -> 41.000863 | L18: =D18/J18 -> 1
C19: SKM | D19: 740 | E19: =VLOOKUP(C19,Master!$B$6:$N$243,9,FALSE) -> gr | F19: =VLOOKUP(C19,Master!B18:N255,10,FALSE) -> 32.432432 | G19: =D19*F19 -> 24000
C20: Susu Evaporasi | D20: 480 | E20: =VLOOKUP(C20,Master!$B$6:$N$243,9,FALSE) -> ml | F20: =VLOOKUP(C20,Master!B19:N256,10,FALSE) -> 44.736842 | G20: =D20*F20 -> 21473.684
A21: 6 | B21: Bar Pro Lemon Juice | D21: =SUM(D22:D23) -> 660 | E21: =VLOOKUP(B21,Master!B21:N258,9,FALSE) -> ml | G21: =SUM(G22:G23) -> 35218.842 | H21: 0.1 | I21: =G21+(G21*H21) -> 38740.726 | J21: 990 | K21: =I21/J21 -> 39.132047 | L21: =D21/J21 -> 0.66666667
C22: Lemon | D22: 330 | E22: =VLOOKUP(C22,Master!$B$6:$N$243,9,FALSE) -> ml | F22: =VLOOKUP(C22,Master!B21:N258,10,FALSE) -> 106.06061 | G22: =D22*F22 -> 35000
C23: Air Galon | D23: 330 | E23: =VLOOKUP(C23,Master!$B$6:$N$243,9,FALSE) -> ml | F23: =VLOOKUP(C23,Master!B22:N259,10,FALSE) -> 0.66315789 | G23: =D23*F23 -> 218.84211
A24: 7 | B24: Bar Pro Orange Juice | D24: =SUM(D25:D26) -> 660 | E24: =VLOOKUP(B24,Master!B24:N261,9,FALSE) -> ml | G24: =SUM(G25:G26) -> 35218.842 | H24: 0.1 | I24: =G24+(G24*H24) -> 38740.726 | J24: 990 | K24: =I24/J24 -> 39.132047 | L24: =D24/J24 -> 0.66666667
C25: Orange | D25: 330 | E25: =VLOOKUP(C25,Master!$B$6:$N$243,9,FALSE) -> ml | F25: =VLOOKUP(C25,Master!B24:N261,10,FALSE) -> 106.06061 | G25: =D25*F25 -> 35000
C26: Air Galon | D26: 330 | E26: =VLOOKUP(C26,Master!$B$6:$N$243,9,FALSE) -> ml | F26: =VLOOKUP(C26,Master!B25:N262,10,FALSE) -> 0.66315789 | G26: =D26*F26 -> 218.84211
A27: 8 | B27: Bar Pro Simple Syrup | D27: =SUM(D28:D29) -> 2000 | E27: =VLOOKUP(B27,Master!B27:N264,9,FALSE) -> ml | G27: =SUM(G28:G29) -> 18163.158 | H27: 0.1 | I27: =G27+(G27*H27) -> 19979.474 | J27: 1250 | K27: =I27/J27 -> 15.983579 | L27: =D27/J27 -> 1.6
C28: Gula hijau | D28: 1000 | E28: =VLOOKUP(C28,Master!$B$6:$N$243,9,FALSE) -> gr | F28: =VLOOKUP(C28,Master!B27:N264,10,FALSE) -> 17.5 | G28: =D28*F28 -> 17500
C29: Air Galon | D29: 1000 | E29: =VLOOKUP(C29,Master!$B$6:$N$243,9,FALSE) -> ml | F29: =VLOOKUP(C29,Master!B28:N265,10,FALSE) -> 0.66315789 | G29: =D29*F29 -> 663.15789
A30: 9 | B30: Bar Pro Syrup Lemon | D30: =SUM(D31:D32) -> 300 | E30: =VLOOKUP(B30,Master!B30:N267,9,FALSE) -> ml | G30: =SUM(G31:G32) -> 4752.1968 | H30: 0.1 | I30: =G30+(G30*H30) -> 5227.4165 | J30: 40 | K30: =I30/J30 -> 130.68541 | L30: =D30/J30 -> 7.5
C31: Lemon Syrup 460ml | D31: 100 | E31: =VLOOKUP(C31,Master!$B$6:$N$243,9,FALSE) -> ml | F31: =VLOOKUP(C31,Master!B30:N267,10,FALSE) -> 46.195652 | G31: =D31*F31 -> 4619.5652
C32: Air Galon | D32: 200 | E32: =VLOOKUP(C32,Master!$B$6:$N$243,9,FALSE) -> ml | F32: =VLOOKUP(C32,Master!B31:N268,10,FALSE) -> 0.66315789 | G32: =D32*F32 -> 132.63158
A33: 10 | B33: Bar Pro Thai Tea | D33: =SUM(D34:D35) -> 2090 | E33: =VLOOKUP(B33,Master!B33:N270,9,FALSE) -> ml | G33: =SUM(G34:G35) -> 13926.316 | H33: 0.1 | I33: =G33+(G33*H33) -> 15318.947 | J33: 160 | K33: =I33/J33 -> 95.743421 | L33: =D33/J33 -> 13.0625
C34: Thai Black Tea 400 gr | D34: 90 | E34: =VLOOKUP(C34,Master!$B$6:$N$243,9,FALSE) -> gr | F34: =VLOOKUP(C34,Master!B33:N270,10,FALSE) -> 140 | G34: =D34*F34 -> 12600
C35: Air Galon | D35: 2000 | E35: =VLOOKUP(C35,Master!$B$6:$N$243,9,FALSE) -> ml | F35: =VLOOKUP(C35,Master!B34:N271,10,FALSE) -> 0.66315789 | G35: =D35*F35 -> 1326.3158
A36: 11 | B36: Bar Pro espresso | D36: =SUM(D37:D38) -> 2200 | E36: =VLOOKUP(B36,Master!B36:N273,9,FALSE) -> porsi | G36: =SUM(G37:G38) -> 195795.79 | H36: 0.1 | I36: =G36+(G36*H36) -> 215375.37 | J36: 55 | K36: =I36/J36 -> 3915.9158 | L36: =D36/J36 -> 40
C37: Beans | D37: 1000 | E37: =VLOOKUP(C37,Master!$B$6:$N$1000,9,FALSE) -> gr | F37: =VLOOKUP(C37,Master!B36:N1000,10,FALSE) -> 195 | G37: =D37*F37 -> 195000
C38: Air Galon | D38: 1200 | E38: =VLOOKUP(C38,Master!$B$6:$N$1000,9,FALSE) -> ml | F38: =VLOOKUP(C38,Master!B37:N1001,10,FALSE) -> 0.66315789 | G38: =D38*F38 -> 795.78947
A39: 12 | B39: Bar Pro Cold Brew | D39: =SUM(D40:D41) -> 2500 | E39: =VLOOKUP(B39,Master!B39:N276,9,FALSE) -> ml | G39: =SUM(G40:G41) -> 81326.316 | H39: 0.1 | I39: =G39+(G39*H39) -> 89458.947 | J39: 20 | K39: =I39/J39 -> 4472.9474 | L39: =D39/J39 -> 125
C40: Beans Blend 50:50 | D40: 500 | E40: =VLOOKUP(C40,Master!$B$6:$N$1000,9,FALSE) -> gr | F40: =VLOOKUP(C40,Master!B39:N1003,10,FALSE) -> 160 | G40: =D40*F40 -> 80000
C41: Air Galon | D41: 2000 | E41: =VLOOKUP(C41,Master!$B$6:$N$1000,9,FALSE) -> ml | F41: =VLOOKUP(C41,Master!B40:N1004,10,FALSE) -> 0.66315789 | G41: =D41*F41 -> 1326.3158
...

Sheet List Bahan Burtok
I1: 9 | J1: 10 | K1: PO | M1: PO | O1: PO
A2: List Bahan | B2: Kode | C2: Kategori | D2: Lokasi | E2: Qty | F2: Kemasan | G2: Ukuran | H2: Satuan | I2: Jumlah | J2: Harga per pcs/ml/gr | K2: PO | L2: Sat | M2: PO | N2: Sat | O2: PO | P2: Sat | Q2: Cek
A3: KTC Daging Sop | B3: Z-001 | C3: KTC | D3: Central Kitchen | E3: 1 | F3: gr | H3: gr | J3: 217.8 | L3: pak | N3: pak | P3: pak | Q3: FALSE
A4: KTC Kuah | B4: Z-002 | C4: KTC | D4: Central Kitchen | E4: 1 | F4: ml | H4: ml | J4: 2.2183333 | L4: pak | N4: pak | P4: pak | Q4: FALSE
A5: KTC Perkedel | B5: Z-003 | C5: KTC | D5: Central Kitchen | E5: 1 | F5: pcs | H5: pcs | J5: 1071.0526 | L5: pak | N5: pak | P5: pak | Q5: FALSE
A6: KTC Saikoro | B6: Z-004 | C6: KTC | D6: Central Kitchen | E6: 1 | F6: tusuk | H6: tusuk | J6: 6002.4242 | L6: pak | N6: pak | P6: pak | Q6: FALSE
A7: KTC Garlic Oil | B7: Z-005 | C7: KTC | D7: Central Kitchen | E7: 1 | F7: gr | H7: gr | J7: 120.84749 | L7: pak | N7: pak | P7: pak | Q7: FALSE
A8: KTC Daging Iris | B8: Z-006 | C8: KTC | D8: Central Kitchen | E8: 1 | F8: tusuk | H8: tusuk | J8: 2194.5 | L8: pak | N8: pak | P8: pak | Q8: FALSE
A9: KTC Jukut Goreng | B9: Z-007 | C9: KTC | D9: Central Kitchen | E9: 1 | F9: porsi | H9: porsi | J9: 2438.9444 | L9: pak | N9: pak | P9: pak | Q9: FALSE
A10: KTC Bawang Putih Goreng | B10: Z-008 | C10: KTC | D10: Central Kitchen | E10: 1 | F10: gr | H10: gr | J10: 179.36111 | L10: pak | N10: pak | P10: pak | Q10: FALSE
A11: KTC Bawang Putih Mentah | B11: Z-009 | C11: KTC | D11: Central Kitchen | E11: 1 | F11: gr | H11: gr | J11: 179.36111 | L11: pak | N11: pak | P11: pak | Q11: FALSE
A12: KTC Oil Ijo | B12: Z-010 | C12: KTC | D12: Central Kitchen | E12: 1 | F12: ml | H12: ml | L12: pak | N12: pak | P12: pak | Q12: FALSE
A13: KTC Oil Merah | B13: Z-011 | C13: KTC | D13: Central Kitchen | E13: 1 | F13: ml | H13: ml | L13: pak | N13: pak | P13: pak | Q13: FALSE
A14: KTC Sambal Sop | B14: Z-012 | C14: KTC | D14: Central Kitchen | E14: 1 | F14: gr | H14: gr | L14: pak | N14: pak | P14: pak | Q14: FALSE
A15: Krupuk DDN isi 10 | B15: ZA-004 | C15: Bahan Pokok | D15: Gudang Burtok | E15: 1 | F15: pak | G15: 10 | H15: pcs | I15: 4200 | J15: =I15/G15 -> 420 | L15: pak | N15: pak | P15: pak | Q15: FALSE
A16: Jeruk Nipis 1kg | B16: ZA-005 | C16: Bahan Pokok | D16: Gudang Burtok | E16: 1 | F16: pak | G16: 34 | H16: pcs | I16: 23000 | J16: =I16/G16 -> 676.47059 | L16: pak | N16: pak | P16: pak | Q16: FALSE
A17: Telur Pitan Isi 4 | B17: ZA-006 | C17: Bahan Pokok | D17: Gudang Burtok | E17: 1 | F17: pak | G17: 4 | H17: pcs | I17: 37800 | J17: =I17/G17 -> 9450 | L17: pak | N17: pak | P17: pak | Q17: FALSE
A18: Telur Bebek Asin Isi 6 | B18: ZA-007 | C18: Bahan Pokok | D18: Gudang Burtok | E18: 1 | F18: pak | G18: 6 | H18: pcs | I18: 47950 | J18: =I18/G18 -> 7991.6667 | L18: pak | N18: pak | P18: pak | Q18: FALSE
A19: Telur Bebek Asin Mentah Isi 6 | B19: ZA-008 | C19: Bahan Pokok | D19: Gudang Burtok | E19: 1 | F19: pak | G19: 6 | H19: pcs | I19: 43250 | J19: =I19/G19 -> 7208.3333 | L19: pak | N19: pak | P19: pak | Q19: FALSE
